<sdf version='1.6'>
  <model name='X3'>
    <pose>0 0 0.053302 0 0 0</pose>

    
    <link name='X3/base_link'>
      <pose frame=''>0 0 0 0 -0 0</pose>
      <inertial>
        <pose frame=''>0 0 0 0 -0 0</pose>
        <mass>4.6</mass>
        <inertia>
          <ixx>0.423</ixx>
          <ixy>0</ixy>
          <ixz>0</ixz>
          <iyy>0.423</iyy>
          <iyz>0</iyz>
          <izz>0.828</izz>
        </inertia>
      </inertial>
      <collision name='X3/base_link_inertia_collision'>
        <pose frame=''>0 0 0 0 -0 0</pose>
        <geometry>
          <box>
            <size>1.2 1.2 0.15</size>
          </box>
        </geometry>
      </collision>
      <visual name='X3/base_link_inertia_visual'>
        <pose frame=''>0 0 0 0 -0 0</pose>
        <geometry>
          <mesh>
            <scale>1 1 1</scale>
            <uri>model://x3/meshes/x3.dae</uri>
          </mesh>
        </geometry>
      </visual>

      <!-- Octocopter carbon arms for visual reference -->
      <visual name='arm_0'>
        <pose>0.3 0.0 0 0 1.5708 0</pose>
        <geometry>
          <cylinder>
            <radius>0.02</radius>
            <length>0.6</length>
          </cylinder>
        </geometry>
        <material>
          <diffuse>0.1 0.1 0.1 1</diffuse>
        </material>
      </visual>
      <visual name='arm_1'>
        <pose>0.2121 0.2121 0 0 1.5708 0.7854</pose>
        <geometry>
          <cylinder>
            <radius>0.02</radius>
            <length>0.6</length>
          </cylinder>
        </geometry>
        <material>
          <diffuse>0.1 0.1 0.1 1</diffuse>
        </material>
      </visual>
      <visual name='arm_2'>
        <pose>0.0 0.3 0 0 1.5708 1.5708</pose>
        <geometry>
          <cylinder>
            <radius>0.02</radius>
            <length>0.6</length>
          </cylinder>
        </geometry>
        <material>
          <diffuse>0.1 0.1 0.1 1</diffuse>
        </material>
      </visual>
      <visual name='arm_3'>
        <pose>-0.2121 0.2121 0 0 1.5708 2.35619</pose>
        <geometry>
          <cylinder>
            <radius>0.02</radius>
            <length>0.6</length>
          </cylinder>
        </geometry>
        <material>
          <diffuse>0.1 0.1 0.1 1</diffuse>
        </material>
      </visual>
      <visual name='arm_4'>
        <pose>-0.3 0.0 0 0 1.5708 3.14159</pose>
        <geometry>
          <cylinder>
            <radius>0.02</radius>
            <length>0.6</length>
          </cylinder>
        </geometry>
        <material>
          <diffuse>0.1 0.1 0.1 1</diffuse>
        </material>
      </visual>
      <visual name='arm_5'>
        <pose>-0.2121 -0.2121 0 0 1.5708 -2.35619</pose>
        <geometry>
          <cylinder>
            <radius>0.02</radius>
            <length>0.6</length>
          </cylinder>
        </geometry>
        <material>
          <diffuse>0.1 0.1 0.1 1</diffuse>
        </material>
      </visual>
      <visual name='arm_6'>
        <pose>0.0 -0.3 0 0 1.5708 -1.5708</pose>
        <geometry>
          <cylinder>
            <radius>0.02</radius>
            <length>0.6</length>
          </cylinder>
        </geometry>
        <material>
          <diffuse>0.1 0.1 0.1 1</diffuse>
        </material>
      </visual>
      <visual name='arm_7'>
        <pose>0.2121 -0.2121 0 0 1.5708 -0.7854</pose>
        <geometry>
          <cylinder>
            <radius>0.02</radius>
            <length>0.6</length>
          </cylinder>
        </geometry>
        <material>
          <diffuse>0.1 0.1 0.1 1</diffuse>
        </material>
      </visual>

      <!-- IMU Sensor -->
      <sensor name="imu_sensor" type="imu">
        <pose>0 0 0 0 0 0</pose>
        <always_on>1</always_on>
        <update_rate>100</update_rate>
        <topic>/imu/data</topic>
        <imu>
          <angular_velocity>
            <x>
              <noise type="gaussian">
                <mean>0.0</mean>
                <stddev>0.0001</stddev>
              </noise>
            </x>
            <y>
              <noise type="gaussian">
                <mean>0.0</mean>
                <stddev>0.0001</stddev>
              </noise>
            </y>
            <z>
              <noise type="gaussian">
                <mean>0.0</mean>
                <stddev>0.0001</stddev>
              </noise>
            </z>
          </angular_velocity>
          <linear_acceleration>
            <x>
              <noise type="gaussian">
                <mean>0.0</mean>
                <stddev>0.001</stddev>
              </noise>
            </x>
            <y>
              <noise type="gaussian">
                <mean>0.0</mean>
                <stddev>0.001</stddev>
              </noise>
            </y>
            <z>
              <noise type="gaussian">
                <mean>0.0</mean>
                <stddev>0.001</stddev>
              </noise>
            </z>
          </linear_acceleration>
          <enable_orientation>true</enable_orientation>
        </imu>
      </sensor>
     
    </link>



    <link name='camera_link'>
      <!-- Camera positioned forward and tilted downward for ground surveillance -->
      <!-- Position: 0.2m forward from center, tilted 30 degrees down (0.5236 rad) -->
      <pose frame=''>0.2 0 0 0 0.5236 0</pose>
      <inertial>
        <pose frame=''>0 0 0 0 0 0</pose>
        <mass>0.001</mass>
        <inertia>
          <ixx>1e-6</ixx>
          <ixy>0</ixy>
          <ixz>0</ixz>
          <iyy>1e-6</iyy>
          <iyz>0</iyz>
          <izz>1e-6</izz>
        </inertia>
      </inertial>

      <sensor name="camera_front" type="camera">
        <pose>0 0 0 0 0 0</pose>
        <always_on>1</always_on>
        <update_rate>30</update_rate>
        <topic>/camera/image_raw</topic>
        
        <camera>
            <horizontal_fov>1.2</horizontal_fov>
            <distortion>
                <k1>0.0</k1>
                <k2>0.0</k2>
                <k3>0.0</k3>
                <p1>0.0</p1>
                <p2>0.0</p2>
                <center>0.5 0.5</center>
            </distortion>
            <image>
                <width>640</width>
                <height>480</height>
                <format>R8G8B8</format>
            </image>
            <clip>
                <near>0.5</near>
                <far>50</far>
            </clip>
            <noise>
                <type>gaussian</type>
                <mean>0</mean>
                <stddev>0.005</stddev>
            </noise>
            
            <!-- IMPORTANT: Set the correct frame_id for ROS optical frame convention -->
            <frame_id>X3/camera_optical_frame</frame_id>
            <camera_info_topic>/camera/camera_info</camera_info_topic>
        </camera>
      </sensor>
    </link>

    <!-- Optical frame with correct ROS camera convention AND downward tilt -->
    <link name='camera_optical_frame'>
      <!-- Apply both the downward tilt AND the optical frame transformation -->
      <!-- First: 30° pitch down (0.5236 rad), then ROS optical transform -->
      <!-- Combined: pitch=0.5236 + roll=-π/2 + yaw=-π/2 -->
      <pose frame=''>0.2 0 0 -1.5708 0.5236 -1.5708</pose>
      <inertial>
        <pose frame=''>0 0 0 0 0 0</pose>
        <mass>0.001</mass>
        <inertia>
          <ixx>1e-6</ixx>
          <ixy>0</ixy>
          <ixz>0</ixz>
          <iyy>1e-6</iyy>
          <iyz>0</iyz>
          <izz>1e-6</izz>
        </inertia>
      </inertial>
    </link>

    <!-- Fixed joint to connect camera link to base -->
    <joint name='X3/camera_joint' type='fixed'>
      <child>camera_link</child>
      <parent>X3/base_link</parent>
    </joint>

    <!-- Fixed joint to connect optical frame to camera link -->
    <joint name='camera_optical_joint' type='fixed'>
      <child>camera_optical_frame</child>
      <parent>camera_link</parent>
      <!-- Apply ONLY the ROS optical frame transformation here -->
      <!-- The downward tilt is already in the camera_link pose -->
      <pose>0 0 0 -1.5708 0 -1.5708</pose>
    </joint>

    <!-- Octocopter rotor layout (radius 1.2 m) -->
    <!-- rotor_index, pose(x y z), propeller direction alternates CCW/CW -->
    <link name='X3/rotor_0'>
      <pose frame=''>0.6 0.0 0.03 0 -0 0</pose>
      <inertial>
        <pose frame=''>0 0 0 0 -0 0</pose>
        <mass>0.05</mass>
        <inertia>
          <ixx>9.75e-06</ixx>
          <ixy>0</ixy>
          <ixz>0</ixz>
          <iyy>4.17041e-04</iyy>
          <iyz>0</iyz>
          <izz>4.26041e-04</izz>
        </inertia>
      </inertial>
      <collision name='X3/rotor_0_collision'>
        <pose frame=''>0 0 0 0 -0 0</pose>
        <geometry>
          <cylinder>
            <length>0.01</length>
            <radius>0.12</radius>
          </cylinder>
        </geometry>
      </collision>
      <visual name='X3/rotor_0_visual'>
        <pose frame=''>0 0 0 0 -0 0</pose>
        <geometry>
          <mesh>
            <scale>0.12 0.12 0.12</scale>
            <uri>model://x3/meshes/propeller_ccw.dae</uri>
          </mesh>
        </geometry>
        <material>
          <script>
            <name>Gazebo/Blue</name>
            <uri>file://media/materials/scripts/gazebo.material</uri>
          </script>
        </material>
      </visual>
    </link>
    <joint name='X3/rotor_0_joint' type='revolute'>
      <child>X3/rotor_0</child>
      <parent>X3/base_link</parent>
      <axis>
        <xyz>0 0 1</xyz>
        <limit>
          <lower>-1e+16</lower>
          <upper>1e+16</upper>
        </limit>
        <use_parent_model_frame>1</use_parent_model_frame>
      </axis>
    </joint>

    <link name='X3/rotor_1'>
      <pose frame=''>0.4243 0.4243 0.03 0 -0 0</pose>
      <inertial>
        <pose frame=''>0 0 0 0 -0 0</pose>
        <mass>0.05</mass>
        <inertia>
          <ixx>9.75e-06</ixx>
          <ixy>0</ixy>
          <ixz>0</ixz>
          <iyy>4.17041e-04</iyy>
          <iyz>0</iyz>
          <izz>4.26041e-04</izz>
        </inertia>
      </inertial>
      <collision name='X3/rotor_1_collision'>
        <pose frame=''>0 0 0 0 -0 0</pose>
        <geometry>
          <cylinder>
            <length>0.01</length>
            <radius>0.12</radius>
          </cylinder>
        </geometry>
      </collision>
      <visual name='X3/rotor_1_visual'>
        <pose frame=''>0 0 0 0 -0 0</pose>
        <geometry>
          <mesh>
            <scale>0.12 0.12 0.12</scale>
            <uri>model://x3/meshes/propeller_cw.dae</uri>
          </mesh>
        </geometry>
        <material>
          <script>
            <name>Gazebo/Red</name>
            <uri>file://media/materials/scripts/gazebo.material</uri>
          </script>
        </material>
      </visual>
    </link>
    <joint name='X3/rotor_1_joint' type='revolute'>
      <child>X3/rotor_1</child>
      <parent>X3/base_link</parent>
      <axis>
        <xyz>0 0 1</xyz>
        <limit>
          <lower>-1e+16</lower>
          <upper>1e+16</upper>
        </limit>
        <use_parent_model_frame>1</use_parent_model_frame>
      </axis>
    </joint>

    <link name='X3/rotor_2'>
      <pose frame=''>0.0 0.6 0.03 0 -0 0</pose>
      <inertial>
        <pose frame=''>0 0 0 0 -0 0</pose>
        <mass>0.05</mass>
        <inertia>
          <ixx>9.75e-06</ixx>
          <ixy>0</ixy>
          <ixz>0</ixz>
          <iyy>4.17041e-04</iyy>
          <iyz>0</iyz>
          <izz>4.26041e-04</izz>
        </inertia>
      </inertial>
      <collision name='X3/rotor_2_collision'>
        <pose frame=''>0 0 0 0 -0 0</pose>
        <geometry>
          <cylinder>
            <length>0.01</length>
            <radius>0.12</radius>
          </cylinder>
        </geometry>
      </collision>
      <visual name='X3/rotor_2_visual'>
        <pose frame=''>0 0 0 0 -0 0</pose>
        <geometry>
          <mesh>
            <scale>0.12 0.12 0.12</scale>
            <uri>model://x3/meshes/propeller_ccw.dae</uri>
          </mesh>
        </geometry>
        <material>
          <script>
            <name>Gazebo/Blue</name>
            <uri>file://media/materials/scripts/gazebo.material</uri>
          </script>
        </material>
      </visual>
    </link>
    <joint name='X3/rotor_2_joint' type='revolute'>
      <child>X3/rotor_2</child>
      <parent>X3/base_link</parent>
      <axis>
        <xyz>0 0 1</xyz>
        <limit>
          <lower>-1e+16</lower>
          <upper>1e+16</upper>
        </limit>
        <use_parent_model_frame>1</use_parent_model_frame>
      </axis>
    </joint>

    <link name='X3/rotor_3'>
      <pose frame=''>-0.4243 0.4243 0.03 0 -0 0</pose>
      <inertial>
        <pose frame=''>0 0 0 0 -0 0</pose>
        <mass>0.05</mass>
        <inertia>
          <ixx>9.75e-06</ixx>
          <ixy>0</ixy>
          <ixz>0</ixz>
          <iyy>4.17041e-04</iyy>
          <iyz>0</iyz>
          <izz>4.26041e-04</izz>
        </inertia>
      </inertial>
      <collision name='X3/rotor_3_collision'>
        <pose frame=''>0 0 0 0 -0 0</pose>
        <geometry>
          <cylinder>
            <length>0.01</length>
            <radius>0.12</radius>
          </cylinder>
        </geometry>
      </collision>
      <visual name='X3/rotor_3_visual'>
        <pose frame=''>0 0 0 0 -0 0</pose>
        <geometry>
          <mesh>
            <scale>0.12 0.12 0.12</scale>
            <uri>model://x3/meshes/propeller_cw.dae</uri>
          </mesh>
        </geometry>
        <material>
          <script>
            <name>Gazebo/Red</name>
            <uri>file://media/materials/scripts/gazebo.material</uri>
          </script>
        </material>
      </visual>
    </link>
    <joint name='X3/rotor_3_joint' type='revolute'>
      <child>X3/rotor_3</child>
      <parent>X3/base_link</parent>
      <axis>
        <xyz>0 0 1</xyz>
        <limit>
          <lower>-1e+16</lower>
          <upper>1e+16</upper>
        </limit>
        <use_parent_model_frame>1</use_parent_model_frame>
      </axis>
    </joint>

    <link name='X3/rotor_4'>
      <pose frame=''>-0.6 0.0 0.03 0 -0 0</pose>
      <inertial>
        <pose frame=''>0 0 0 0 -0 0</pose>
        <mass>0.05</mass>
        <inertia>
          <ixx>9.75e-06</ixx>
          <ixy>0</ixy>
          <ixz>0</ixz>
          <iyy>4.17041e-04</iyy>
          <iyz>0</iyz>
          <izz>4.26041e-04</izz>
        </inertia>
      </inertial>
      <collision name='X3/rotor_4_collision'>
        <pose frame=''>0 0 0 0 -0 0</pose>
        <geometry>
          <cylinder>
            <length>0.01</length>
            <radius>0.12</radius>
          </cylinder>
        </geometry>
      </collision>
      <visual name='X3/rotor_4_visual'>
        <pose frame=''>0 0 0 0 -0 0</pose>
        <geometry>
          <mesh>
            <scale>0.12 0.12 0.12</scale>
            <uri>model://x3/meshes/propeller_ccw.dae</uri>
          </mesh>
        </geometry>
        <material>
          <script>
            <name>Gazebo/Blue</name>
            <uri>file://media/materials/scripts/gazebo.material</uri>
          </script>
        </material>
      </visual>
    </link>
    <joint name='X3/rotor_4_joint' type='revolute'>
      <child>X3/rotor_4</child>
      <parent>X3/base_link</parent>
      <axis>
        <xyz>0 0 1</xyz>
        <limit>
          <lower>-1e+16</lower>
          <upper>1e+16</upper>
        </limit>
        <use_parent_model_frame>1</use_parent_model_frame>
      </axis>
    </joint>

    <link name='X3/rotor_5'>
      <pose frame=''>-0.4243 -0.4243 0.03 0 -0 0</pose>
      <inertial>
        <pose frame=''>0 0 0 0 -0 0</pose>
        <mass>0.05</mass>
        <inertia>
          <ixx>9.75e-06</ixx>
          <ixy>0</ixy>
          <ixz>0</ixz>
          <iyy>4.17041e-04</iyy>
          <iyz>0</iyz>
          <izz>4.26041e-04</izz>
        </inertia>
      </inertial>
      <collision name='X3/rotor_5_collision'>
        <pose frame=''>0 0 0 0 -0 0</pose>
        <geometry>
          <cylinder>
            <length>0.01</length>
            <radius>0.12</radius>
          </cylinder>
        </geometry>
      </collision>
      <visual name='X3/rotor_5_visual'>
        <pose frame=''>0 0 0 0 -0 0</pose>
        <geometry>
          <mesh>
            <scale>0.12 0.12 0.12</scale>
            <uri>model://x3/meshes/propeller_cw.dae</uri>
          </mesh>
        </geometry>
        <material>
          <script>
            <name>Gazebo/Red</name>
            <uri>file://media/materials/scripts/gazebo.material</uri>
          </script>
        </material>
      </visual>
    </link>
    <joint name='X3/rotor_5_joint' type='revolute'>
      <child>X3/rotor_5</child>
      <parent>X3/base_link</parent>
      <axis>
        <xyz>0 0 1</xyz>
        <limit>
          <lower>-1e+16</lower>
          <upper>1e+16</upper>
        </limit>
        <use_parent_model_frame>1</use_parent_model_frame>
      </axis>
    </joint>

    <link name='X3/rotor_6'>
      <pose frame=''>0.0 -0.6 0.03 0 -0 0</pose>
      <inertial>
        <pose frame=''>0 0 0 0 -0 0</pose>
        <mass>0.05</mass>
        <inertia>
          <ixx>9.75e-06</ixx>
          <ixy>0</ixy>
          <ixz>0</ixz>
          <iyy>4.17041e-04</iyy>
          <iyz>0</iyz>
          <izz>4.26041e-04</izz>
        </inertia>
      </inertial>
      <collision name='X3/rotor_6_collision'>
        <pose frame=''>0 0 0 0 -0 0</pose>
        <geometry>
          <cylinder>
            <length>0.01</length>
            <radius>0.12</radius>
          </cylinder>
        </geometry>
      </collision>
      <visual name='X3/rotor_6_visual'>
        <pose frame=''>0 0 0 0 -0 0</pose>
        <geometry>
          <mesh>
            <scale>0.12 0.12 0.12</scale>
            <uri>model://x3/meshes/propeller_ccw.dae</uri>
          </mesh>
        </geometry>
        <material>
          <script>
            <name>Gazebo/Blue</name>
            <uri>file://media/materials/scripts/gazebo.material</uri>
          </script>
        </material>
      </visual>
    </link>
    <joint name='X3/rotor_6_joint' type='revolute'>
      <child>X3/rotor_6</child>
      <parent>X3/base_link</parent>
      <axis>
        <xyz>0 0 1</xyz>
        <limit>
          <lower>-1e+16</lower>
          <upper>1e+16</upper>
        </limit>
        <use_parent_model_frame>1</use_parent_model_frame>
      </axis>
    </joint>

    <link name='X3/rotor_7'>
      <pose frame=''>0.4243 -0.4243 0.03 0 -0 0</pose>
      <inertial>
        <pose frame=''>0 0 0 0 -0 0</pose>
        <mass>0.05</mass>
        <inertia>
          <ixx>9.75e-06</ixx>
          <ixy>0</ixy>
          <ixz>0</ixz>
          <iyy>4.17041e-04</iyy>
          <iyz>0</iyz>
          <izz>4.26041e-04</izz>
        </inertia>
      </inertial>
      <collision name='X3/rotor_7_collision'>
        <pose frame=''>0 0 0 0 -0 0</pose>
        <geometry>
          <cylinder>
            <length>0.01</length>
            <radius>0.12</radius>
          </cylinder>
        </geometry>
      </collision>
      <visual name='X3/rotor_7_visual'>
        <pose frame=''>0 0 0 0 -0 0</pose>
        <geometry>
          <mesh>
            <scale>0.12 0.12 0.12</scale>
            <uri>model://x3/meshes/propeller_cw.dae</uri>
          </mesh>
        </geometry>
        <material>
          <script>
            <name>Gazebo/Red</name>
            <uri>file://media/materials/scripts/gazebo.material</uri>
          </script>
        </material>
      </visual>
    </link>
    <joint name='X3/rotor_7_joint' type='revolute'>
      <child>X3/rotor_7</child>
      <parent>X3/base_link</parent>
      <axis>
        <xyz>0 0 1</xyz>
        <limit>
          <lower>-1e+16</lower>
          <upper>1e+16</upper>
        </limit>
        <use_parent_model_frame>1</use_parent_model_frame>
      </axis>
    </joint>

    <!-- VelocityControl removed - using MulticopterVelocityControl from world file instead -->

    <!-- Odometry publisher plugin -->
    <plugin filename="gz-sim8-odometry-publisher-system" name="gz::sim::systems::OdometryPublisher">
      <odom_frame>world</odom_frame>
      <robot_base_frame>X3/base_link</robot_base_frame>
      <dimensions>3</dimensions>
      <odom_topic>/X3/odometry</odom_topic>
      <odom_publish_frequency>50</odom_publish_frequency>
    </plugin>


  </model>
</sdf>
